Workbook

Sheet Nomenclador de Procedimientos y
A1: NRO | B1: CO_RUC | C1: CO_CODIGO | D1: DE_PROCEDIMIENTO | E1: CO_GRUPO_CONTABLE | F1: DE_GRUPO_CONTABLE | G1: DE_DETALLE_VALIDACION | H1: DE_UNIDAD | I1: CO_ESTANDAR | J1: DE_ESTADO
A2: 1 | B2: 20393857677 | C2: 001701 | D2: CONSULTAS EN EMERGENCIA DIURNO POR MEDICO ESPECIALISTA | E2: 1 | F2: HONORARIOS Y PROCEDIMIENTOS MEDICOS Y QUIRURGICOS | H2: 0.00 | I2: 99284 | J2: Activo
A3: 2 | B3: 20393857677 | C3: 001703 | D3: CONSULTAS EN EMERGENCIA DIURNO POR MEDICO DE GUARDIA-EMERGENCISTA | E3: 1 | F3: HONORARIOS Y PROCEDIMIENTOS MEDICOS Y QUIRURGICOS | H3: 0.00 | I3: 99284 | J3: Activo
A4: 3 | B4: 20393857677 | C4: 001704 | D4: CONSULTAS EN EMERGENCIA NOCTURNO POR.MEDICO ESPECIALISTA - EMERGENCIA | E4: 1 | F4: HONORARIOS Y PROCEDIMIENTOS MEDICOS Y QUIRURGICOS | H4: 0.00 | I4: 99284 | J4: Activo
A5: 4 | B5: 20393857677 | C5: 001706 | D5: CONSULTA EN EMERGENCIA NOCTURNO POR MEDICO DE GUARDIA.EMERGENCISTA | E5: 1 | F5: HONORARIOS Y PROCEDIMIENTOS MEDICOS Y QUIRURGICOS | H5: 0.00 | I5: 99284 | J5: Activo
A6: 5 | B6: 20393857677 | C6: 001721 | D6: CURACION PEQUE¿A | E6: 1 | F6: HONORARIOS Y PROCEDIMIENTOS MEDICOS Y QUIRURGICOS | H6: 3.00 | I6: 15854 | J6: Activo
A7: 6 | B7: 20393857677 | C7: 001722 | D7: CURACION MEDIANA | E7: 1 | F7: HONORARIOS Y PROCEDIMIENTOS MEDICOS Y QUIRURGICOS | H7: 5.00 | I7: 15854 | J7: Activo
A8: 7 | B8: 20393857677 | C8: 001723 | D8: CURACION GRANDE | E8: 1 | F8: HONORARIOS Y PROCEDIMIENTOS MEDICOS Y QUIRURGICOS | H8: 6.00 | I8: 15880 | J8: Activo
A9: 8 | B9: 20393857677 | C9: 001731 | D9: SUTURA DE 1 A 4 PUNTOS | E9: 1 | F9: HONORARIOS Y PROCEDIMIENTOS MEDICOS Y QUIRURGICOS | H9: 8.33 | I9: 12001 | J9: Activo
A10: 9 | B10: 20393857677 | C10: 001732 | D10: SUTURA DE 5 A 10 PUNTOS | E10: 1 | F10: HONORARIOS Y PROCEDIMIENTOS MEDICOS Y QUIRURGICOS | H10: 17.00 | I10: 12002 | J10: Activo
A11: 10 | B11: 20393857677 | C11: 001733 | D11: SUTURA MAS DE 10 PUNTOS | E11: 1 | F11: HONORARIOS Y PROCEDIMIENTOS MEDICOS Y QUIRURGICOS | H11: 25.00 | I11: 12005 | J11: Activo
A12: 11 | B12: 20393857677 | C12: 001741 | D12: TOPICO - PEQUE¿AS.ABCESOS,CUERPOS EXTRA¿OS, LIPOMAS, U¿AS, ETC. | E12: 3 | F12: HOTELERIA, SERVICIO CLINICO Y TOPICO | H12: 0.00 | I12: 10060 | J12: Activo
A13: 12 | B13: 20393857677 | C13: 001742 | D13: YESOS, VENDAS, PUESTAS,CAMBIO, RETIRO, ETC. | E13: 1 | F13: HONORARIOS Y PROCEDIMIENTOS MEDICOS Y QUIRURGICOS | H13: 0.00 | I13: 29799 | J13: Activo
... A167: 166 | B167: 20393857677 | C167: 090710 | D167: LIBER.ADHERENCIAS.BALANO-PREPUCIALES | E167: 1 | F167: HONORARIOS Y PROCEDIMIENTOS MEDICOS Y QUIRURGICOS | H167: 12.00 | I167: 54450 | J167: Activo
A168: 167 | B168: 20393857677 | C168: 100001 | D168: SUITE TIPO I | E168: 3 | F168: HOTELERIA, SERVICIO CLINICO Y TOPICO | J168: Activo
A169: 168 | B169: 20393857677 | C169: 100002 | D169: SUITE TIPO II | E169: 3 | F169: HOTELERIA, SERVICIO CLINICO Y TOPICO | J169: Activo
A170: 169 | B170: 20393857677 | C170: 100003 | D170: CUARTO INDIVIDUAL CON BAÑO, CON SOFA CAMA Y/O SILLON RECLINABLE | E170: 3 | F170: HOTELERIA, SERVICIO CLINICO Y TOPICO | J170: Activo
A171: 170 | B171: 20393857677 | C171: 100004 | D171: CUARTO INDIVIDUAL CON BAÑO CON CAMA DE ACOMPANANTE | E171: 3 | F171: HOTELERIA, SERVICIO CLINICO Y TOPICO | J171: Activo
A172: 171 | B172: 20393857677 | C172: 100005 | D172: CUARTO INDIVIDUAL CON MEDIO BAÑO CON CAMA DE ACOMPANANTE | E172: 3 | F172: HOTELERIA, SERVICIO CLINICO Y TOPICO | J172: Activo
A173: 172 | B173: 20393857677 | C173: 100006 | D173: CUARTO INDIVIDUAL CON BAÑO | E173: 3 | F173: HOTELERIA, SERVICIO CLINICO Y TOPICO | J173: Activo
A174: 173 | B174: 20393857677 | C174: 100007 | D174: CUARTO INDIVIDUAL SIN BAÑO | E174: 3 | F174: HOTELERIA, SERVICIO CLINICO Y TOPICO | J174: Activo
A175: 174 | B175: 20393857677 | C175: 100008 | D175: CUARTO INDIVIDUAL DE PEDIATRIA | E175: 3 | F175: HOTELERIA, SERVICIO CLINICO Y TOPICO | J175: Activo
A176: 175 | B176: 20393857677 | C176: 100009 | D176: CUARTO DOBLE CON BAÑO | E176: 3 | F176: HOTELERIA, SERVICIO CLINICO Y TOPICO | J176: Activo
A177: 176 | B177: 20393857677 | C177: 100010 | D177: CUARTO DOBLE SIN BAÑO | E177: 3 | F177: HOTELERIA, SERVICIO CLINICO Y TOPICO | J177: Activo
A178: 177 | B178: 20393857677 | C178: 100011 | D178: CUARTO DOBLE DE PEDIATRIA | E178: 3 | F178: HOTELERIA, SERVICIO CLINICO Y TOPICO | J178: Activo
A179: 178 | B179: 20393857677 | C179: 100012 | D179: CUARTO MULTIPLE | E179: 3 | F179: HOTELERIA, SERVICIO CLINICO Y TOPICO | J179: Activo
... A182: 181 | B182: 20393857677 | C182: 100102 | D182: REPOSO POST-OPERATORIO HASTA 2 HORAS | E182: 3 | F182: HOTELERIA, SERVICIO CLINICO Y TOPICO | J182: Activo
A183: 182 | B183: 20393857677 | C183: 100103 | D183: OOFORECTOMIA O SALPINGO-OOFORECTOMIA UNILATERAL | E183: 1 | F183: HONORARIOS Y PROCEDIMIENTOS MEDICOS Y QUIRURGICOS | H183: 155.00 | I183: 58943 | J183: Activo
A184: 183 | B184: 20393857677 | C184: 100104 | D184: OOFORECTOMIA O SALPINGO-OOFORECTOMIA BILATERAL | E184: 1 | F184: HONORARIOS Y PROCEDIMIENTOS MEDICOS Y QUIRURGICOS | H184: 155.00 | I184: 58943 | J184: Activo
A185: 184 | B185: 20393857677 | C185: 100105 | D185: REPARACION Y PLASTIA DE OVARIO y/o TROMPA | E185: 1 | F185: HONORARIOS Y PROCEDIMIENTOS MEDICOS Y QUIRURGICOS | H185: 155.00 | I185: 58670 | J185: Activo
A186: 185 | B186: 20393857677 | C186: 100106 | D186: LIGADURA DE TROMPAS-UNICA OPERACI¿N | E186: 1 | F186: HONORARIOS Y PROCEDIMIENTOS MEDICOS Y QUIRURGICOS | H186: 107.00 | I186: 58600 | J186: Activo
A187: 186 | B187: 20393857677 | C187: 100201 | D187: BIOPSIA DE ENDOMETRIO / CERVIX - SIN DILATACION CON HISTEROLISIS | E187: 1 | F187: HONORARIOS Y PROCEDIMIENTOS MEDICOS Y QUIRURGICOS | H187: 17.00 | I187: 58100 | J187: Activo
A188: 187 | B188: 20393857677 | C188: 100202 | D188: ELECTROCOAGULACION DE CUELLO UTERINO / EXTIRPACION DE LESION LOCAL DE CUELLO UTERINO / POLIPO | E188: 1 | F188: HONORARIOS Y PROCEDIMIENTOS MEDICOS Y QUIRURGICOS | H188: 29.00 | I188: 57500 | J188: Activo
A189: 188 | B189: 20393857677 | C189: 100203 | D189: CERCLAJE CUELLO UTERINO-TRAQUELORRAFIA -FUERA DEL PARTO- | E189: 1 | F189: HONORARIOS Y PROCEDIMIENTOS MEDICOS Y QUIRURGICOS | H189: 36.00 | I189: 57720 | J189: Activo
A190: 189 | B190: 20393857677 | C190: 100204 | D190: CONIZACION CUELLO UTERINO -TRAQUELOCTOMIA C/S LEGRADO UTERINO | E190: 1 | F190: HONORARIOS Y PROCEDIMIENTOS MEDICOS Y QUIRURGICOS | H190: 48.00 | I190: 57522 | J190: Activo
A191: 190 | B191: 20393857677 | C191: 100205 | D191: DILATACION Y CURETAJE | E191: 1 | F191: HONORARIOS Y PROCEDIMIENTOS MEDICOS Y QUIRURGICOS | H191: 41.00 | I191: 58120 | J191: Activo
A192: 191 | B192: 20393857677 | C192: 100206 | D192: DILATACION y CURETAJE C/ELECTROCOAGULACION | E192: 1 | F192: HONORARIOS Y PROCEDIMIENTOS MEDICOS Y QUIRURGICOS | H192: 48.00 | I192: 59840 | J192: Activo
A193: 192 | B193: 20393857677 | C193: 100207 | D193: HISTEROPEXIA-MANCHESTER S/PLASTIA | E193: 1 | F193: HONORARIOS Y PROCEDIMIENTOS MEDICOS Y QUIRURGICOS | H193: 60.00 | I193: 58400 | J193: Activo
A194: 193 | B194: 20393857677 | C194: 100208 | D194: HISTEROPEXIA-MANCHESTER C/PLASTIA VAGINAL | E194: 1 | F194: HONORARIOS Y PROCEDIMIENTOS MEDICOS Y QUIRURGICOS | H194: 131.00 | I194: 57210 | J194: Activo
... A213: 212 | B213: 20393857677 | C213: 100311 | D213: TRATAMIENTO.QUIRURGICO.FISTULA PERINEAL -PERINEO PLASTIA | E213: 1 | F213: HONORARIOS Y PROCEDIMIENTOS MEDICOS Y QUIRURGICOS | H213: 60.00 | I213: 46270 | J213: Activo
...

Sheet Robles
B2: NOMENCLADOR CLINICA ROBLES
A3: Ruc | B3: Codigo | C3: Descripcion | D3: CodContable | E3: Descripcion Contable
A4: 20606729449 | B4: 00027 | D4: 1 | E4: HONORARIOS Y PROCEDIMIENTOS MÉDICOS Y QUIRÚRGICOS
A7: 20606729449 | B7: 220101 | C7: 30% DE LOS HONORARIOS DEL CIRUJANO | D7: 1 | E7: HONORARIOS Y PROCEDIMIENTOS MÉDICOS Y QUIRÚRGICOS
A8: 20606729449 | B8: 080212 | C8: ABDOMINOPLASTIA POST TRAUMATICA / POST INFECCIOSA CON / SIN RECONSTRUCCION DE CICATRIZ UMBILICAL | D8: 1 | E8: HONORARIOS Y PROCEDIMIENTOS MÉDICOS Y QUIRÚRGICOS
A9: 20606729449 | B9: 230204 | C9: ABLACION DE FOCO ARRITMOGENICO POR RADIOFRECUENCIA | D9: 1 | E9: HONORARIOS Y PROCEDIMIENTOS MÉDICOS Y QUIRÚRGICOS
A10: 20606729449 | B10: 110109 | C10: ABLACION DE UÑA | D10: 1 | E10: HONORARIOS Y PROCEDIMIENTOS MÉDICOS Y QUIRÚRGICOS
A11: 20606729449 | B11: 100217 | C11: ABLACION HISTEROSCOPICA DE ENDOMETRIO | D11: 1 | E11: HONORARIOS Y PROCEDIMIENTOS MÉDICOS Y QUIRÚRGICOS
A12: 20606729449 | B12: 080507 | C12: ABSCESO PERIANAL - DRENAJE | D12: 1 | E12: HONORARIOS Y PROCEDIMIENTOS MÉDICOS Y QUIRÚRGICOS
A13: 20606729449 | B13: 450111 | C13: ACELERADOR LINEAL - CONFORMACIONAL | D13: 1 | E13: HONORARIOS Y PROCEDIMIENTOS MÉDICOS Y QUIRÚRGICOS
A14: 20606729449 | B14: 450109 | C14: ACELERADOR LINEAL - ELECTRONES (E) | D14: 1 | E14: HONORARIOS Y PROCEDIMIENTOS MÉDICOS Y QUIRÚRGICOS
A15: 20606729449 | B15: 450108 | C15: ACELERADOR LINEAL - FOTONES (F) | D15: 1 | E15: HONORARIOS Y PROCEDIMIENTOS MÉDICOS Y QUIRÚRGICOS
A16: 20606729449 | B16: 450110 | C16: ACELERADOR LINEAL - HIPERFRACCIONAMIENTO | D16: 1 | E16: HONORARIOS Y PROCEDIMIENTOS MÉDICOS Y QUIRÚRGICOS
A17: 20606729449 | B17: 240203 | C17: ACTINOTERAPIA SIMPLE O COMBINADA POR SESION | D17: 1 | E17: HONORARIOS Y PROCEDIMIENTOS MÉDICOS Y QUIRÚRGICOS
A18: 20606729449 | B18: 030805 | C18: ADENOIDECTOMIA | D18: 1 | E18: HONORARIOS Y PROCEDIMIENTOS MÉDICOS Y QUIRÚRGICOS
... A4846: 20606729449 | B4846: 101946 | C4846: VENTILADOR MECANICO VOLUMETRICO REGULADO POR PRESION | D4846: 9 | E4846: OTROS

Sheet Robles-SF
B2: NOMENCLADOR CLINICA ROBLES
A3: Ruc | B3: Codigo | C3: Descripcion | D3: CodContable | E3: Descripcion Contable
A4: 20606729449 | B4: 331003 | C4: "PERFIL HEPATICO (COMPRENDE TGO, TGP,,PROTEINAS TOTALES Y FRACCIONADAS, FOSFATASA | D4: 4 | E4: EXAMENES AUXILIARES DE LABORATORIO
A5: 20606729449 | B5: 1 | C5: 11 DEOXYCORTISOL - COMPUESTOS | D5: 4 | E5: EXAMENES AUXILIARES DE LABORATORIO
A6: 20606729449 | B6: 331207 | C6: 17 HIDROXIPROGESTERONA | D6: 4 | E6: EXAMENES AUXILIARES DE LABORATORIO
A7: 20606729449 | B7: 331208 | C7: 17 HODROXICORTICOIDE | D7: 4 | E7: EXAMENES AUXILIARES DE LABORATORIO
A8: 20606729449 | B8: 1 | C8: 1ERA CESAREA PLAN MADRE | D8: 5 | E8: DIAGNOSTICO X IMAGENES Y OTROS DE AYUDA
A9: 20606729449 | B9: 500268 | C9: 2DA CESAREA + LIGADURA PLAN MADRE | D9: 5 | E9: DIAGNOSTICO X IMAGENES Y OTROS DE AYUDA
A10: 20606729449 | B10: 500267 | C10: 2DA CESAREA PLAN MADRE | D10: 5 | E10: DIAGNOSTICO X IMAGENES Y OTROS DE AYUDA
A11: 20606729449 | B11: 220101 | C11: 30% DE LOS HONORARIOS DEL CIRUJANO | D11: 1 | E11: HONORARIOS Y PROCEDIMIENTOS MÉDICOS Y QUIRÚRGICOS
A12: 20606729449 | B12: 1 | C12: 3ERA CESAREA | D12: 5 | E12: DIAGNOSTICO X IMAGENES Y OTROS DE AYUDA
A13: 20606729449 | B13: 500270 | C13: 3ERA CESAREA + LIGADURA PLAN MADRE | D13: 5 | E13: DIAGNOSTICO X IMAGENES Y OTROS DE AYUDA
A14: 20606729449 | B14: 440712 | C14: 5 COLOCACION DE MARCAPASO | D14: 5 | E14: DIAGNOSTICO X IMAGENES Y OTROS DE AYUDA
A15: 20606729449 | B15: 330853 | C15: 5 HIDROXINDOLACETICO | D15: 4 | E15: EXAMENES AUXILIARES DE LABORATORIO
... A3695: 20606729449 | B3695: 331316 | C3695: ZINC EN SUERO | D3695: 4 | E3695: EXAMENES AUXILIARES DE LABORATORIO
A3696: 20606729449 | B3696: 00027 | D3696: 1 | E3696: HONORARIOS Y PROCEDIMIENTOS MÉDICOS Y QUIRÚRGICOS

Sheet Hoja2
B2: Cruce | C2: Existe | D2: No Existe | E2: Descripción
B3: =VLOOKUP('Robles-SF'!B4,'Nomenclador de Procedimientos y'!$C$2:$D$3877,1,FALSE) -> 331003 | C3: =IF(ISNA(B3),"",B3) -> 331003 | D3: =IF(ISNA(B3),'Robles-SF'!B4,"") | E3: =IF(EXACT(D3, ""), VLOOKUP(C3,'Nomenclador de Procedimientos y'!$C$2:$D$3877,2,FALSE), VLOOKUP(D3,'Robles-SF'!$B$4:$C$3696,2,FALSE)) -> PERFIL HEPATICO (COMPRENDE TGO, TGP, PROTEINAS, FOSFATASA ALCALINA, BILIRRUBINAS)
B4: =VLOOKUP('Robles-SF'!B5,'Nomenclador de Procedimientos y'!$C$2:$D$3877,1,FALSE) -> #N/A | C4: =IF(ISNA(B4),"",B4) | D4: =IF(ISNA(B4),'Robles-SF'!B5,"") -> 1 | E4: =IF(EXACT(D4, ""), VLOOKUP(C4,'Nomenclador de Procedimientos y'!$C$2:$D$3877,2,FALSE), VLOOKUP(D4,'Robles-SF'!$B$4:$C$3696,2,FALSE)) -> 11 DEOXYCORTISOL - COMPUESTOS
B5: =VLOOKUP('Robles-SF'!B6,'Nomenclador de Procedimientos y'!$C$2:$D$3877,1,FALSE) -> #N/A | C5: =IF(ISNA(B5),"",B5) | D5: =IF(ISNA(B5),'Robles-SF'!B6,"") -> 331207 | E5: =IF(EXACT(D5, ""), VLOOKUP(C5,'Nomenclador de Procedimientos y'!$C$2:$D$3877,2,FALSE), VLOOKUP(D5,'Robles-SF'!$B$4:$C$3696,2,FALSE)) -> 17 HIDROXIPROGESTERONA
B6: =VLOOKUP('Robles-SF'!B7,'Nomenclador de Procedimientos y'!$C$2:$D$3877,1,FALSE) -> #N/A | C6: =IF(ISNA(B6),"",B6) | D6: =IF(ISNA(B6),'Robles-SF'!B7,"") -> 331208 | E6: =IF(EXACT(D6, ""), VLOOKUP(C6,'Nomenclador de Procedimientos y'!$C$2:$D$3877,2,FALSE), VLOOKUP(D6,'Robles-SF'!$B$4:$C$3696,2,FALSE)) -> 17 HODROXICORTICOIDE
B7: =VLOOKUP('Robles-SF'!B8,'Nomenclador de Procedimientos y'!$C$2:$D$3877,1,FALSE) -> #N/A | C7: =IF(ISNA(B7),"",B7) | D7: =IF(ISNA(B7),'Robles-SF'!B8,"") -> 1 | E7: =IF(EXACT(D7, ""), VLOOKUP(C7,'Nomenclador de Procedimientos y'!$C$2:$D$3877,2,FALSE), VLOOKUP(D7,'Robles-SF'!$B$4:$C$3696,2,FALSE)) -> 11 DEOXYCORTISOL - COMPUESTOS
B8: =VLOOKUP('Robles-SF'!B9,'Nomenclador de Procedimientos y'!$C$2:$D$3877,1,FALSE) -> #N/A | C8: =IF(ISNA(B8),"",B8) | D8: =IF(ISNA(B8),'Robles-SF'!B9,"") -> 500268 | E8: =IF(EXACT(D8, ""), VLOOKUP(C8,'Nomenclador de Procedimientos y'!$C$2:$D$3877,2,FALSE), VLOOKUP(D8,'Robles-SF'!$B$4:$C$3696,2,FALSE)) -> 2DA CESAREA + LIGADURA PLAN MADRE
B9: =VLOOKUP('Robles-SF'!B10,'Nomenclador de Procedimientos y'!$C$2:$D$3877,1,FALSE) -> #N/A | C9: =IF(ISNA(B9),"",B9) | D9: =IF(ISNA(B9),'Robles-SF'!B10,"") -> 500267 | E9: =IF(EXACT(D9, ""), VLOOKUP(C9,'Nomenclador de Procedimientos y'!$C$2:$D$3877,2,FALSE), VLOOKUP(D9,'Robles-SF'!$B$4:$C$3696,2,FALSE)) -> 2DA CESAREA PLAN MADRE
B10: =VLOOKUP('Robles-SF'!B11,'Nomenclador de Procedimientos y'!$C$2:$D$3877,1,FALSE) -> 220101 | C10: =IF(ISNA(B10),"",B10) -> 220101 | D10: =IF(ISNA(B10),'Robles-SF'!B11,"") | E10: =IF(EXACT(D10, ""), VLOOKUP(C10,'Nomenclador de Procedimientos y'!$C$2:$D$3877,2,FALSE), VLOOKUP(D10,'Robles-SF'!$B$4:$C$3696,2,FALSE)) -> TRANSFERENCIA O REORGANIZACION DE TEJIDO ADYACENTE / Z-PLASTIA / W-PLASTIA / V-Y-PLASTIA - POR DEFECTO MENOR O IGUAL A 10 CM2
B11: =VLOOKUP('Robles-SF'!B12,'Nomenclador de Procedimientos y'!$C$2:$D$3877,1,FALSE) -> #N/A | C11: =IF(ISNA(B11),"",B11) | D11: =IF(ISNA(B11),'Robles-SF'!B12,"") -> 1 | E11: =IF(EXACT(D11, ""), VLOOKUP(C11,'Nomenclador de Procedimientos y'!$C$2:$D$3877,2,FALSE), VLOOKUP(D11,'Robles-SF'!$B$4:$C$3696,2,FALSE)) -> 11 DEOXYCORTISOL - COMPUESTOS
B12: =VLOOKUP('Robles-SF'!B13,'Nomenclador de Procedimientos y'!$C$2:$D$3877,1,FALSE) -> #N/A | C12: =IF(ISNA(B12),"",B12) | D12: =IF(ISNA(B12),'Robles-SF'!B13,"") -> 500270 | E12: =IF(EXACT(D12, ""), VLOOKUP(C12,'Nomenclador de Procedimientos y'!$C$2:$D$3877,2,FALSE), VLOOKUP(D12,'Robles-SF'!$B$4:$C$3696,2,FALSE)) -> 3ERA CESAREA + LIGADURA PLAN MADRE
B13: =VLOOKUP('Robles-SF'!B14,'Nomenclador de Procedimientos y'!$C$2:$D$3877,1,FALSE) -> 440712 | C13: =IF(ISNA(B13),"",B13) -> 440712 | D13: =IF(ISNA(B13),'Robles-SF'!B14,"") | E13: =IF(EXACT(D13, ""), VLOOKUP(C13,'Nomenclador de Procedimientos y'!$C$2:$D$3877,2,FALSE), VLOOKUP(D13,'Robles-SF'!$B$4:$C$3696,2,FALSE)) -> 5 COLOCACION DE MARCAPASO
B14: =VLOOKUP('Robles-SF'!B15,'Nomenclador de Procedimientos y'!$C$2:$D$3877,1,FALSE) -> 330853 | C14: =IF(ISNA(B14),"",B14) -> 330853 | D14: =IF(ISNA(B14),'Robles-SF'!B15,"") | E14: =IF(EXACT(D14, ""), VLOOKUP(C14,'Nomenclador de Procedimientos y'!$C$2:$D$3877,2,FALSE), VLOOKUP(D14,'Robles-SF'!$B$4:$C$3696,2,FALSE)) -> 55 HIDROXINDOLACETICO
... B3878: =VLOOKUP('Robles-SF'!B3879,'Nomenclador de Procedimientos y'!$C$2:$D$3877,1,FALSE) -> #N/A | C3878: =IF(ISNA(B3878),"",B3878) | D3878: =IF(ISNA(B3878),'Robles-SF'!B3879,"") -> 0 | E3878: =IF(EXACT(D3878, ""), VLOOKUP(C3878,'Nomenclador de Procedimientos y'!$C$2:$D$3877,2,FALSE), VLOOKUP(D3878,'Robles-SF'!$B$4:$C$3696,2,FALSE)) -> #N/A

Sheet Relacion
B2: EXISTE | C2: NO EXISTE | D2: DESCRIPCIÓN
B3: 331003 | D3: PERFIL HEPATICO (COMPRENDE TGO, TGP, PROTEINAS, FOSFATASA ALCALINA, BILIRRUBINAS)
C4: 1 | D4: 11 DEOXYCORTISOL - COMPUESTOS
C5: 331207 | D5: 17 HIDROXIPROGESTERONA
C6: 331208 | D6: 17 HODROXICORTICOIDE
C7: 1 | D7: 11 DEOXYCORTISOL - COMPUESTOS
C8: 500268 | D8: 2DA CESAREA + LIGADURA PLAN MADRE
C9: 500267 | D9: 2DA CESAREA PLAN MADRE
B10: 220101 | D10: TRANSFERENCIA O REORGANIZACION DE TEJIDO ADYACENTE / Z-PLASTIA / W-PLASTIA / V-Y-PLASTIA - POR DEFECTO MENOR O IGUAL A 10 CM2
C11: 1 | D11: 11 DEOXYCORTISOL - COMPUESTOS
C12: 500270 | D12: 3ERA CESAREA + LIGADURA PLAN MADRE
B13: 440712 | D13: 5 COLOCACION DE MARCAPASO
B14: 330853 | D14: 55 HIDROXINDOLACETICO
B15: 440722 | D15: 5 LITOTRICIA POR NEFROSTOMIA
C16: 331209 | D16: 5' NUCLEOTIDASA
C17: 331210 | D17: 6 BETA HIDROXICORTISOL
C18: 331211 | D18: 6 MONOACETILMORFINA
C19: 1 | D19: 11 DEOXYCORTISOL - COMPUESTOS
C20: 080212 | D20: ABDOMINOPLASTIA POST TRAUMATICA / POST INFECCIOSA CON / SIN RECONSTRUCCION DE CICATRIZ UMBILICAL
C21: 230204 | D21: ABLACION DE FOCO ARRITMOGENICO POR RADIOFRECUENCIA
B22: 110109 | D22: ABLACION DE U¿A
B23: 100217 | D23: ABLACION ENDOMETRIO HISTEROSCOPICO
B24: 080507 | D24: ABSCESO PERIANAL-DRENAJE-
C25: 331703 | D25: ACAROS - INVESTIGACION
C26: 450111 | D26: ACELERADOR LINEAL - CONFORMACIONAL
C27: 450109 | D27: ACELERADOR LINEAL - ELECTRONES (E)
C28: 450108 | D28: ACELERADOR LINEAL - FOTONES (F)
C29: 450110 | D29: ACELERADOR LINEAL - HIPERFRACCIONAMIENTO
B30: 330707 | D30: ACETAMINOFEN
C31: 1 | D31: 11 DEOXYCORTISOL - COMPUESTOS
C32: 331212 | D32: ACETONA SERICA
B33: 330525 | D33: ACETONA URINARIA
C34: 331214 | D34: ACIDO CITRICO EN LIQUIDO SEMINAL
B35: 330922 | D35: ACIDO DELTA AMINOLEVULINICO
B36: 330421 | D36: ACIDO FOLICO INTRAERITROCITARIO
C37: 280306 | D37: ACIDO HOMOGENTISICO 'ALCAPTONURIA'
C38: 331217 | D38: ACIDO HOMOVANILICO
B39: 330101 | D39: ACIDO URICO
C40: 1 | D40: 11 DEOXYCORTISOL - COMPUESTOS
C41: 1 | D41: 11 DEOXYCORTISOL - COMPUESTOS
...
